Workbook
Name _.: '[1]Summary table'!#REF!
Name _.: '[1]Summary table'!#REF!
Name _.: '[1]Summary table'!#REF!
Name _\0: #REF!
Name _\A: #REF!
Name _\b: [2]BaseMone!#REF!
Name _\c: '[3]PAG-28'!$CD$97
Name _\CORR: [4]BATERIA!#REF!
Name _\D: #REF!
Name _\E: #REF!
Name _\F: #REF!
Name _\G: #REF!
Name _\H: #REF!
Name _\I: #REF!
Name _\J: #REF!
Name _\K: #REF!
Name _\L: #REF!
Name _\m: #REF!
Name _\N: #REF!
Name _\O: #REF!
Name _\p: '[5]Prog-2011'!#REF!
Name _\Q: #REF!
Name _\R: #REF!
Name _\S: #REF!
Name _\T: [6]A!#REF!
Name _\U: #REF!
Name _\V: #REF!
Name _\W: #REF!
Name _\X: #REF!
Name _\Y: #REF!
Name _\Z: [6]A!#REF!
Name __\0: #REF!
Name __\A: #REF!
Name __\b: [2]BaseMone!#REF!
Name __\CORR: [4]BATERIA!#REF!
Name __\D: #REF!
Name __\E: #REF!
Name __\F: #REF!
Name __\G: #REF!
Name __\H: #REF!
Name __\I: #REF!
Name __\J: #REF!
Name __\K: #REF!
Name __\L: #REF!
Name __\m: #REF!
Name __\N: #REF!
Name __\O: #REF!
Name __\p: '[5]Prog-2011'!#REF!
Name __\Q: #REF!
Name __\R: #REF!
Name __\S: #REF!
Name __\T: [6]A!#REF!
Name __\U: #REF!
Name __\V: #REF!
Name __\W: #REF!
Name __\X: #REF!
Name __\Y: #REF!
Name __\Z: [6]A!#REF!
Name ___\0: #REF!
Name ___\A: #REF!

Sheet Form 1.1
B2: FORMULARIO N° 1.1
B4: RESUMEN DE LA ARTICULACIÓN DE ACCIONES DE MEDIANO PLAZO DEL PLAN ESTRATÉGICO INSTITUCIONAL
B6: GESTIÓN: | D6: 2026
B7: ENTIDAD: | D7: 596 - EMPRESA PÚBLICA TRANSPORTE AÉREO MILITAR
B9: ARTICULACIÓN AL PDES (A) | E9: ACCIÓN DE MEDIANO PLAZO ( B) | G9: INDICADORES (C) | M9: PROGRAMACIÓN DE METAS* (D)
B10: E | C10: M | D10: R | E10: DENOMINACIÓN | F10: PRODUCTO O RESULTADO | G10: DESCRIPCIÓN DEL INDICADOR | H10: UNIDAD DE MEDIDA | I10: FÓRMULA | J10: LÍNEA BASE (2025) | K10: RESULTADO DE MEDIANO PLAZO (PEI 2020-2025) | L10: ESTIMACIÓN DE METAS DE MEDIANO PLAZO* (2026-2030) | M10: 2024 | N10: EJEC. | O10: 2025 | P10: EJEC. (ESTIMADO A DIC.) | Q10: 2026 | R10: 2027 | S10: 2028 | T10: 2029 | U10: 2030
M11: PROG. | O11: PROG. | Q11: PROG. | R11: PROG. | S11: PROG. | T11: PROG. | U11: PROG.
B12: 7 | C12: 1 | D12: 7 | E12: Establecer al 100% una gestión administrativa empresarial eficiente con capacitación del personal y cooperación interinstitucional a nivel nacional. | F12: Gestión administrativa eficaz de la empresa en el quinquenio a nivel nacional. | G12: (%) grado de eficacia en la gestión administrativa a nivel producto | H12: Porcentaje | I12: Resultado alcanzado x 100 / resultado previsto | J12: 0 | K12: 0 | L12: 1 | M12: 0.2 | N12: 0.18 | O12: 0.2 | P12: 0.18 | Q12: 0.15 | R12: 0.0001 | S12: 0.0001 | T12: 0.0001 | U12: 0.0001
C13: 5 | D13: 1 | E13: Efectuar al 100% la Gestión Economica y financiera proyectado por la empresa a nivel nacional. | F13: Gestión económica y financiera eficaz de la empresa en el quinquenio a nivel nacional. | G13: (%) grado de eficacia en la generación de ingresos | H13: Porcentaje | I13: Ingresos generados / Ingresos proyectados x 100 | J13: 0 | K13: 0 | L13: 1 | M13: 0.33 | N13: 0.27 | O13: 0.33 | P13: 0.28 | Q13: 0.25 | R13: 0.0005 | S13: 0.0005 | T13: 0.0005 | U13: 0.0005
E14: Incrementar del 1% al 21% la participación en el mercado de transporte aéreo, para integrar a la población en rutas alejadas a nivel nacional. | F14: Incremento del servicio de transporte aéreo a nivel nacional en el quinquenio. | G14: (%) de participación en el mercado en el servicio de transporte aéreo. | H14: Porcentaje | I14: Transporte de pasajeros, carga y correo regular y no regular a nivel nacional de EPTAM/Transporte de pasajeros , carga y correo regular y no regular a nivel nacional del mercado aéronautico)*100 | J14: 0.01 | K14: 0.01 | L14: 0.21 | M14: 0.07 | N14: 0.0314 | O14: 0.07 | P14: 0.05 | Q14: 0.1 | R14: 0.0001 | S14: 0.0001 | T14: 0.0001 | U14: 0.0001
E15: Incrementar en 10 rutas aéreas en operación, mecanismos de control de seguridad operacional a nivel nacional. | F15: Rutas aéreas en operación con mecanismos de control y seguridad, que integran al país a nivel nacional en el quinquenio. | G15: Nro. de Rutas en operación. | H15: Numero | I15: N/A | J15: 0 | K15: 0 | L15: 10 | M15: 8 | N15: 8 | O15: 10 | P15: 10 | Q15: 10 | R15: 0.1 | S15: 0.1 | T15: 0.1 | U15: 0.1
B22: RESPONSABLES DE LOS COMPROMISOS | G22: NOMBRE Y CARGO | Q22: FIRMA
B23: MAE
B24: RESPONSABLE DE PLANIFICACIÓN
B25: RESPONSABLE DE PRESUPUESTO
B26: RESPONSABLE QUE ELABORA
N27: FECHA:
B28: *De carácter referencial para las gestiones 2025 - 2030 PROG.: Programado EJEC.: Ejecución

Sheet Form 1.2
B2: FORMULARIO N° 1.2
B4: RESUMEN DE LA ARTICULACIÓN DE ACCIONES DE MEDIANO PLAZO Y ACCIONES DE CORTO PLAZO
B6: GESTIÓN: 2027
B7: ENTIDAD: 596 - EMPRESA PÚBLICA TRANSPORTE AÉREO MILITAR
B9: ACCIÓN DE MEDIANO PLAZO (A) PRELIMINAR | E9: ACCIÓN DE CORTO PLAZO (B) | H9: INDICADORES (C) | N9: PROGRAMACIÓN DE METAS 2026* (D)
B10: COD. | C10: DENOMINACIÓN | D10: PRODUCTO O RESULTADO | E10: COD. | F10: DENOMINACIÓN | G10: PRODUCTO | H10: DESCRIPCIÓN DEL INDICADOR | I10: UNIDAD DE MEDIDA | J10: FÓRMULA | K10: LÍNEA BASE 2024 | L10: ESTIMACIÓN 2025 | M10: PROGRAMACIÓN 2026 | N10: PRIMER TRIMESTRE | O10: SEGUNDO TRIMESTRE | P10: TERCER TRIMESTRE | Q10: CUARTO TRIMESTRE
B11: 1.1 | C11: Efectuar al 100% la gestión administrativa de la empresa con cooperación interinstitucional a nivel nacional. | D11: Gestión administrativa eficaz de la empresa en el quinquenio a nivel nacional. | E11: 1.1.1 | F11: Fortalecer la gestión institucional mediante la mejora continua de los procesos, la modernización tecnológica, y el fortalecimiento de la transparencia institucional a nivel nacional en el año 2027. | G11: Gestión institucional de la EPTAM modernizada, con procesos priorizados mejorados, herramientas digitales implementadas de forma progresiva, y mecanismos de transparencia y eficiencia institucional consolidados. | H11: % de cumplimiento de las metas de gestión institucional administrativa | I11: Porcentaje | J11: (Avance fisico de actividades administrativas/ programación de actividades administrativas) *100 | K11: 0.154 | L11: 0.18 | M11: 1 | N11: 0.25 | O11: 0.25 | P11: 0.25 | Q11: 0.25
B12: 2.1 | C12: Efectuar al 100% la Gestión Economica y financiera proyectado por la empresa a nivel nacional. | D12: Gestión económica y financiera eficaz de la empresa en el quinquenio a nivel nacional. | E12: 2.1.1 | F12: Fortalecer la gestión financiera de la Empresa Pública Transporte Aéreo Militar mediante la administración eficiente de los recursos, contribuyendo a la sostenibilidad y al desarrollo empresarial en la gestión 2027 | G12: Gestión financiera fortalecida, con una administración eficiente y oportuna de los recursos institucionales. | H12: % de cumplimiento de las metas de gestión financiera. | I12: Porcentaje | J12: (Avance físico de actividades de gestión financiera / Programación de actividades de gestión financiera) × 100 | K12: 0.2336 | L12: 0.28 | M12: 1 | N12: 0.25 | O12: 0.25 | P12: 0.25 | Q12: 0.25
B13: 3.1 | C13: Incrementar del 1% al 21% la participación en el mercado de transporte aéreo, para integrar a la población en rutas alejadas a nivel nacional. | D13: Incremento del servicio de transporte aéreo a nivel nacional en el quinquenio. | E13: 3.1.1 | F13: Incrementar la participación en el mercado de transporte aéreo de pasajeros, carga y correo, mediante la implementación de estrategias comerciales, a nivel nacional en el año 2027 | G13: Servicio de transporte aéreo de pasajeros, carga y correo prestado a nivel nacional, mediante la implementación de estrategias comerciales | H13: % de pasajeros transportados respecto a los pasajeros programados. | I13: Porcentaje | J13: (N° de pasajeros transportados/N°de pasajeros programados para transporte aéreo​)×100 | K13: 0.053 | L13: 0.05 | M13: 1
B14: 4.1 | C14: Incrementar en 10 rutas aéreas en operación, mecanismos de control de seguridad operacional a nivel nacional. | D14: Rutas aéreas en operación con mecanismos de control y seguridad, que integran al país a nivel nacional en el quinquenio. | E14: 4.1.1 | F14: Gestionar la prestación segura, eficiente y continua de las operaciones aeronáuticas mediante la gestión integral de la flota aérea, la aeronavegabilidad continua y el cumplimiento de los estándares de seguridad operacional a nivel nacional en la gestión 2027 | G14: Flota operativa y aeronavegable, con seguridad operacional gestionada de forma permanente, para la prestación segura y eficiente de los servicios de transporte aéreo. | H14: (%) de cumplimiento de actividades de operaciones, aeronavegabilidad y seguridad operacional para mantener la aeronave operable | I14: Porcentaje | J14: (Ejecución de actividades de SMS, operaciones y aeronavegavilidad para mantener la aeronave operativa y aeronavegable/ actividades de SMS, Operaciones y Aeronavegabilidad programas ) × 100 | K14: 8 | L14: 10 | M14: 1 | N14: 0.25 | O14: 0.25 | P14: 0.25 | Q14: 0.25
B21: RESPONSABLES DE LOS COMPROMISOS | F21: NOMBRE Y CARGO | O21: FIRMA
B22: MAE
B23: RESPONSABLE DE PLANIFICACIÓN
B24: RESPONSABLE DE PRESUPUESTO
B25: RESPONSABLE QUE ELABORA
O26: FECHA:
B27: *De carácter referencial

Sheet ACCION DE CORTO PLAZO- RESPONSA
B3: RESPONSABLE DE CUMPLIMIENTO DE ACCIONES, RESULTADOS Y METAS
B4: Codigo PEE | C4: Acción institucional especifica | D4: Indicador de proceso | E4: Nro. | F4: Acción de corto plazo Gestión 2026 | G4: Resultado esperado Gestión 2026 | H4: Responsable ACP | I4: Área o unidad organizacional responsable | J4: PROGRAMA
B5: 1.1 | C5: Efectuar al 100% la gestión administrativa de la empresa con cooperación interinstitucional a nivel nacional. | D5: (%) grado de eficacia en la gestión administrativa a nivel producto | E5: 1.1 | F5: ='Form 1.2'!F11 -> Fortalecer la gestión institucional mediante la mejora continua de los procesos, la modernización tecnológica, y el fortalecimiento de la transparencia institucional a nivel nacional en el año 2027. | G5: ='Form 1.2'!G11 -> Gestión institucional de la EPTAM modernizada, con procesos priorizados mejorados, herramientas digitales implementadas de forma progresiva, y mecanismos de transparencia y eficiencia institucional consolidados. | H5: Unidad de Transparencia y Lucha contra la Corrupcion, Unidad de Asesoria Jurídica, Unidad de Auditoria Interna, Unidad de Planificacion, ODECO, CIAC, Gerencia de Informática y Comunicaciones | I5: Unidad de Transparencia y Lucha contra la Corrupción; Unidad de Auditoria Interna, Unidad de Asesoria Juridica, Unidad de Planificación, ODECO, CIAC, Gerencia de Informatica y Comunicaciones | J5: 1 ADMINISTRACION CENTRAL
B6: 2.1 | C6: Efectuar al 100% la Gestión Economica y financiera proyectado por la empresa a nivel nacional. | D6: (%) efectividad de la asignación y uso de recursos en relación con el logro de objetivos de acuerdo a normativa vigente | E6: 2.1. | F6: ='Form 1.2'!F12 -> Fortalecer la gestión financiera de la Empresa Pública Transporte Aéreo Militar mediante la administración eficiente de los recursos, contribuyendo a la sostenibilidad y al desarrollo empresarial en la gestión 2027 | G6: ='Form 1.2'!G12 -> Gestión financiera fortalecida, con una administración eficiente y oportuna de los recursos institucionales. | H6: Gerencia de Asuntos Administrativos | I6: Gerencia de Asuntos Administrativos | J6: 2.1 GESTION FINANCIERA
B7: 3.1 | C7: Incrementar del 1% al 21% la participación en el mercado de transporte aéreo, para integrar a la población en rutas alejadas a nivel nacional. | D7: (%) de participación en el mercado | E7: 410.1 | F7: ='Form 1.2'!F13 -> Incrementar la participación en el mercado de transporte aéreo de pasajeros, carga y correo, mediante la implementación de estrategias comerciales, a nivel nacional en el año 2027 | G7: ='Form 1.2'!G13 -> Servicio de transporte aéreo de pasajeros, carga y correo prestado a nivel nacional, mediante la implementación de estrategias comerciales | H7: Gerencia Comercial, Gerencias Regionales | I7: Gerencia Comercial | J7: 410 SERVICIOS DE TRANSPORTE AÉREO
B8: 4.1 | C8: Incrementar en 10 rutas aéreas en operación, mecanismos de control de seguridad operacional a nivel nacional. | D8: Nro de Rutas Aéreas que ejecutan programas de Control de Seguridad Operacional en regiones con poca accesibilidad aerea | E8: 210.1 | F8: ='Form 1.2'!F14 -> Gestionar la prestación segura, eficiente y continua de las operaciones aeronáuticas mediante la gestión integral de la flota aérea, la aeronavegabilidad continua y el cumplimiento de los estándares de seguridad operacional a nivel nacional en la gestión 2027 | G8: ='Form 1.2'!G14 -> Flota operativa y aeronavegable, con seguridad operacional gestionada de forma permanente, para la prestación segura y eficiente de los servicios de transporte aéreo. | H8: Gerencia de Operaciones; Gerencia de Seguridad Operacional (SMS) y Aseguramiento a la Calidad (QMS); Gerencia de Aeronavegabilidad | I8: Gerencia de Operaciones; Gerencia de Seguridad Operacional (SMS) y Aseguramiento a la Calidad (QMS); Gerencia de Aeronavegabilidad | J8: 210 OPERACIONES FLOTA EPTAM

Sheet OPERACIONES Y TAREAS
B2: CUADRO 3
B3: DETERMINACION DE OPERACIONES Y TAREAS
B5: Código POA | C5: Acción de corto plazo Gestión 2027 | D5: Resultado esperado Gestión 2027 | E5: Operación | F5: Fecha prevista Inicio / Fin | H5: Resultado intermedio esperado | I5: Tarea especifica | J5: Área o Unidad organizacional ejecutora
B6: 1 | C6: ='Form 1.2'!F11 -> Fortalecer la gestión institucional mediante la mejora continua de los procesos, la modernización tecnológica, y el fortalecimiento de la transparencia institucional a nivel nacional en el año 2027. | D6: Gestionar y consolidar un equipo de trabajo capacitado para asegurar una administración eficiente en la Empresa Pública Transporte Aéreo Militar. | E6: Gestionar y coordinar la planificacion y el desarrollo organizacional de la EPTAM, en el marco del SOA y el SPO | F6: 46388 | G6: 46752 | H6: Planificación y desarrollo organizacional de la EPTAM fortalecidos mediante la formulación, seguimiento y evaluación de los instrumentos de gestión, en el marco del SOA y el SPO. | I6: Formular 1 documento del Plan Operativo Anual (POA) 2028 de la EPTAM. | J6: Unidad de Planificacion y Control de Gestion
I7: Realizar 12 oficios de seguimiento mensual del POA 2027 de la EPTAM.
I8: Elaborar 1 informe de seguimiento y evaluacion del POA 2026
I10: Atender 220 solicitudes y requerimientos de las Gerencias en materia de planificación y desarrollo organizacional en el marco de la normativa vigente
I11: Realizar 1 formulario de seguimiento y evaluacion al PEE
E12: Ejecutar el control interno posterior, mediante la realización de trabajos de auditoria de mandato legal y otros programados en base a la evaluación de riesgos de la Empresa Publica Transporte Aéreo Militar; asimismo, aquellas instruidas por las instancias competentes, las cuales permitirán el logro de los objetivos de la empresa. | F12: 46388 | G12: 46752 | H12: Informes emitidos producto de la ejecución de las Auditorias de Confiabilidad de Registros y Estados Financieros a la gestión 2026 y otros trabajos de auditoria programados para la gestión, en cumplimiento a Normas Gubernamentales y/o lineamientos emitidos por la Contraloría General del Estado. | I12: Examen de Confiabilidad de Registros Contables y Estados Financieros al 31 de diciembre de 2026 | J12: Unidad de Auditoria Interna
I13: Relevamiento de Información sobre el Cumplimiento de la labor del Comité del Seguimiento de Control Interno de la EPTAM, establecida en las Resoluciones CGE/112/2022 y CGE/114/2022.
I14: Auditoria de Cumplimiento
I15: Actividades de planificación general y específica, y evaluacion de registros para el Examen de Confiabilidad de Registros Contables y Estados Financieros al 31/12/2027
I16: Otras Actividades no Programadas
E17: Gestionar y fortalecer la implementación de políticas y acciones de transparencia, acceso a la información pública, rendición pública de cuentas, prevención y lucha contra la corrupción en la EPTAM, en el marco de la normativa vigente. | F17: 46388 | G17: 46752 | H17: Transparencia institucional fortalecida mediante la implementación y seguimiento de políticas y acciones de acceso a la información pública, rendición pública de cuentas, prevención y lucha contra la corrupción, en cumplimiento de la normativa vigente. | I17: Organizar y ejecutar la Rendición Pública de Cuentas Final 2026 e Inicial 2027. (4) | J17: Unidad de Transparencia y Lucha contra la Corrupción.
I18: Atender, realizar seguimiento y emitir (12) informes sobre las denuncias por presuntos hechos de corrupción y faltas a la ética pública.
I19: Efectuar Programas de Capacitación Induccion a los servidores públicos de la EPTAM, en el marco de la prevención y lucha contra la corrupción y emitir (4) Informes.
I20: Realizar el seguimiento al cumplimiento de las acciones y emitir (4) informes sobre la ética pública y prevención de la corrupción.
I21: Efectuar controles de supervisión a gerencias a nivel nacional de la - EPTAM y emitir (3) Informes, a efectos de verificar el correcto desarrollo de las actividades Operativas.
E22: Interponer demandas de defensa y realizar el seguimiento a procesos laborales, coactivos, penales, civiles y contenciosos. | F22: 46388 | G22: 46752 | H22: Ejercer acciones de defensa y realizar análisis jurídico en la etapa en la que se encuentren | I22: Elaboración de memoriales, notas, coordinación de audiencias y requerimeintos fiscales. | J22: Unidad de Asesoria Jurídica
E23: Responder a trámites administrativos internos o externos, Directorio, así como de la FAB y Ministerios del Área | F23: 46388 | G23: 46752 | H23: Responder en oportunidad a solicitudes y emitir actas de reunión de Directorio | I23: Realizar análisis e interpretación jurídica, a las solicitudes internas, externas y de Directorio
E24: Seguimiento y defensa de procesos de ejecucion coactiva iniciados por la ATT, coordinación de pagos de procesosos ejecutoriados Y Acciones de repeticion. | F24: 46388 | G24: 46752 | H24: Ejercer acciones legales ante las instancias recursivas previo a la ejecutoria de los procesos coactivos; asi como efectuar las acciones de repeticion de los procesos pagados. | I24: Seguimiento a los procesos en movimiento,y en apelación en estrados judiciales. Y emitir los informes legales y demas actos administrativos para la acciones de repeticion.
E25: Suscribir convenios y/o contratos de acuerdo al giro empresarial y comercial de EPTAM | F25: 1/1/2027 | G25: 46752 | H25: Cumplir con el procedimiento legal para suscribir contratos y convenios en beneficio de EPTAM | I25: Analizar y elaborar, contratos administrativos, comerciales y convenios empresariales de EPTAM.
F26: 46388
E29: Planificar, organizar, desarrollar, ejecutar y evaluar programas de formación, capacitación, entrenamiento y actualización dirigidos a alumnos interesados en el campo de la Aviación y al personal aeronáutico, asi ampliar y matener las competencias técnicas y profesionales conforme a la normativa aeronáutica nacional e internacional, contribuyendo al desarrollo seguro, eficiente y sostenible del sistema de aviación civil. | F29: 46388 | G29: 46752 | H29: Contar con personal aeronáutico competente, certificado y permanentemente actualizado, mediante la ejecución de programas de formación, capacitación y entrenamiento que cumplan con la normativa nacional y los estándares internacionales, fortaleciendo la seguridad operacional, la seguridad de la aviación civil, la eficiencia y la sostenibilidad del sistema de aviación civil. | I29: Ejecución del Curso de Técnicas de Enseñanza Aeronáutica Inicial (TDE Inicial). | J29: Centro de Instrucción de Aviación Civil CIAC TAMEP
I30: Ejecución del Curso de Técnicas de Enseñanza Aeronáutica Recurrente (TDE Recurrente).
I31: Ejecución del Curso para Despachador de Vuelo (DV).
I32: Ejecución del Curso para Tripulante de Cabina de Pasajeros (TCP)
E33: Desarrollar, administrar, controlar y supervisar la Gestión de Reclamaciones Directas y Administrativas, como también, los Proyectos de Gestión de Calidad en el Servicio para la mejora continua; en cumplimiento a las disposiciones emitidas por las autoridades competentes. | F33: 46388 | G33: 46752 | H33: Reclamaciones directas y administrativas sistematizadas, atendidas y resueltas conforme a normativa vigente. | I33: Recepcionar, registrar, clasificar y dar seguimiento a las reclamaciones presentadas por usuarios, asegurando su resolución dentro de los plazos establecidos por la normativa vigente. | J33: ODECO
H34: Proyectos de mejora de la calidad en el servicio diseñados, ejecutados y monitoreados, con participación de las áreas operativas. | I34: Diseñar, implementar y supervisar mecanismos eficaces de atención, seguimiento y resolución de reclamos y sugerencias de los pasajeros, en coordinación con las áreas operativas, asegurando el cumplimiento de los estándares de calidad, normativa vigente y principios de protección al consumidor.
H35: Informes de cumplimiento y seguimiento elaborados y presentados ante autoridades competentes, con recomendaciones de mejora continua. | I35: Elaborar informes mensuales sobre la gestión de reclamaciones y calidad, incluyendo análisis de datos, cumplimiento de metas y recomendaciones para optimizar procesos.
E37: Brindar soporte técnico (Mantenimiento, preventivo ycorrectivo al parque informatico) de EPTAM | F37: 46388 | G37: 46752 | H37: 100 % de avance en mantenimiento de equipos de computación | I37: Realizar la limpieza, actualización, reparacion y cambio de componenetes defectuosos ( si se requiere), ademas de la configuracion del parque informatico (Dispositivos Computacionales) hardware y software. Asimismo la instalacion y/o configuracion de algun otro dispositivo informatico complementario. | J37: Gerencia de Informática y Comunicaciones
I38: Realizar la limpieza, actualización, reparacion y cambio de componenetes defectuosos ( si se requiere), ademas de la configuracion del parque informatico ( Dispositivos Computacionales) hardware y software. Asimismo la instalacion y/o configuracion de algun otro dispositivo informatico complementario. En las oficinas Regionales de EPTAM a nivel nacional.
E39: Renovación del servicio de HOSTING | F39: 46388 | G39: 46752 | H39: Contar con el servicio de alojamiento en un servidor web para el almacenamiento de la base de datos de nuestra pagina web, base de datos del servicio de correo institucional. | I39: Realizar la solicitud de renovacion del servicio de hosting (Alojamiento)
E40: Renovación del servicio de DOMINIO de tamep.bo | F40: 46388 | G40: 46752 | H40: Contar con el Dominio para el acceso a nuestros servicios como ser la página web, sistema de correpondencia y otros. | I40: Realizar la solicitud de renovacion del Dominio tamep.bo
E41: Desarrollar el Sistema de Activos Fijos | F41: 46388 | G41: 46752 | H41: Contar con la gestion de activos fijos en cuanto registro, estado del activo, ubicación, designación (responsable) del activo fijo. | I41: Realizar las fases de: Análisis, Diseño (Modelado Rápido UWE,Diseño de la vista en Vue), Planificación, Creación de los endpoints necesarios en Django REST Framework,o Definición de pipeline del modelo de IA que generará los datos, Desarrollo (Desarrollo de Base de Datos, Desarrollo de Interfaz, frontend Vue, consumo de apis expuesto por la API en Django y se integran los scripts o servicios de IA) y pruebas correspondientes.
E42: Desarrollar el Sistema de Control de Asistencia | F42: 46388 | G42: 46752 | H42: Contar con el control del personal e eptam, en cuanto a la aistencia con el uso GPS para conocer la ubicación del personal en tiempo real y actual. | I42: Realizar las fases de: Análisis, Diseño, Desarrollo (Desarrollo de Base de Datos, Desarrollo de Interfaz, Desarrollo de Métricas), Revisión (mejoras si corresponde) y pruebas correspondientes,
E43: Desarrollar el Sistema de SMS | F43: 46388 | G43: 46752 | H43: Contar el registro (subida de informacion) de reportes de seguridad operacional (voluntarios/obligatorios) informes de auditotira, boletines y promociones de Segura operacional y archivo PAC. | I43: Realizar las fases de: Análisis, Diseño, definir las funcionalidades que el sistema necesita, Desarrollo (Desarrollo de Base de Datos, Desarrollo de Interfaz, Desarrollo de Métricas) y pruebas correspondientes.
E44: Implementar la herramienta Moodle para el CIAC | F44: 46388 | G44: 46752 | H44: Contar con una plataforma, para gestionar y administrar espacios virtuales con los estudiantes compartir contenidos, realizar controles y evaluar el progreso académico de los diferentes cursos dictados por este CIAC | I44: Efectuar las tareas de instalación, maquetación estructural (diseño estructural), configuración de servidores y configuración de roles y permisos dentro de Moodle, indispensable para asegurar que la parametrización del sistema responda eficazmente a las necesidades y asegurando el correcto acceso virtual bajo criterios de alta disponibilidad y usabilidad.
B45: 2 | C45: ='Form 1.2'!F12 -> Fortalecer la gestión financiera de la Empresa Pública Transporte Aéreo Militar mediante la administración eficiente de los recursos, contribuyendo a la sostenibilidad y al desarrollo empresarial en la gestión 2027 | D45: Fortalecer la gestión financiera de la Empresa Pública Transporte Aéreo Militar mediante una administración integral y eficiente de recursos y gastos, alineada con las normativas vigentes, para asegurar la sostenibilidad tras la reactivación de vuelos regulares. | E45: Gestionar las diferentes actividades de la jefatura administrativa a través de sus secciones en el marco de las normas vigentes | F45: 46388 | G45: 46752 | J45: Gerencia de Asuntos Administrativos
E46: Gestionar el manejo de los recursos a través de las diferentes secciones dependientes d la jefatura financiera | F46: 46388 | G46: 46752
...

Sheet FECHA PREVISTA DE INICIO Y FINA
B4: CUADRO 2
B5: RESPONSABLE DE CUMPLIMIENTO DE ACCIONES, RESULTADOS Y METAS
B7: Código POA | C7: Acciones de corto plazo Gestión 2025 | D7: Resultados esperados Gestión 2025 | E7: Cargo del REACP | F7: Fecha prevista de inicio | G7: Fecha prevista de finalización
B8: 1.1. | C8: ='Form 1.2'!F11 -> Fortalecer la gestión institucional mediante la mejora continua de los procesos, la modernización tecnológica, y el fortalecimiento de la transparencia institucional a nivel nacional en el año 2027. | D8: ='Form 1.2'!G11 -> Gestión institucional de la EPTAM modernizada, con procesos priorizados mejorados, herramientas digitales implementadas de forma progresiva, y mecanismos de transparencia y eficiencia institucional consolidados. | E8: Unidad de Transparencia y lucha contra la corrupcion | F8: 01/01/27 | G8: 31/12/27
E9: Unidad de Asesoria Juridica
E10: Unidad de Auditoria Interna
E11: Unidad de Planificación
E12: Centro de Instrucción de Aeronautica Civil (CIAC)
E13: Oficina de Atención al consumidor ODECO
E14: Gerencia de Informatica y Comunicaciones
B15: 2.1. | C15: ='Form 1.2'!F12 -> Fortalecer la gestión financiera de la Empresa Pública Transporte Aéreo Militar mediante la administración eficiente de los recursos, contribuyendo a la sostenibilidad y al desarrollo empresarial en la gestión 2027 | D15: ='Form 1.2'!G12 -> Gestión financiera fortalecida, con una administración eficiente y oportuna de los recursos institucionales. | E15: Gerencia de Asuntos Administrativos | F15: 01/01/27 | G15: 31/12/27
B16: 410.1. | C16: ='Form 1.2'!F13 -> Incrementar la participación en el mercado de transporte aéreo de pasajeros, carga y correo, mediante la implementación de estrategias comerciales, a nivel nacional en el año 2027 | D16: ='ACCION DE CORTO PLAZO- RESPONSA'!G7 -> Servicio de transporte aéreo de pasajeros, carga y correo prestado a nivel nacional, mediante la implementación de estrategias comerciales | E16: Gerencia Comercial | F16: 01/01/27 | G16: 31/12/27
E17: Gerencias Regionales | F17: 01/01/27 | G17: 31/12/27
B21: 210.1. | C21: ='Form 1.2'!F14 -> Gestionar la prestación segura, eficiente y continua de las operaciones aeronáuticas mediante la gestión integral de la flota aérea, la aeronavegabilidad continua y el cumplimiento de los estándares de seguridad operacional a nivel nacional en la gestión 2027 | D21: ='ACCION DE CORTO PLAZO- RESPONSA'!G8 -> Flota operativa y aeronavegable, con seguridad operacional gestionada de forma permanente, para la prestación segura y eficiente de los servicios de transporte aéreo. | E21: Gerencia de Operaciones | F21: 01/01/27 | G21: 31/12/27
E22: Gerencia de Aeronavegabilidad Continua
E23: Gerencia Seguridad Operacional (SMS) y Aseguramiento a la Calidad (QMS)

Sheet CUADRO 4
C1: CUADRO 4
C2: DETERMINACION DE REQUERIMIENTOS
C4: Código POA | D4: Acción de corto plazo Gestión 2026 | E4: Operación | F4: Actividad | G4: bien o servicio demandado | H4: Fecha en la que se requiere | I4: Presupuesto de gasto | K4: N° | L4: OBJETO DE LA CONTRATACION (COMPRA DE BIEN O SERVICIO) | M4: IMPORTE ESIMADO (PRECIO REFERENCIAL) Bs. | N4: MES PROGRAMADO PARA LA COMPRA DEL BIEN O SERVICIO
C5: 1.1.1 | D5: Establecer al 15% una Gestión administrativa empresarial eficiente con capacitación del personal y cooperación interinstitucional a nivel nacional en el año 2026. | E5: Formulación del POA 2027 | H5: Julio - Agosto | K5: 1 | L5: PAPEL | M5: =I5+I9+I14+I21+I23+I34+I43+I51+I54+I63+I73+I80+I112+I147+I181+I199+I223+I243+I262+I287+I16+I60 -> 0 | N5: Enero- Diciembre
H6: Julio - Agosto | K6: 2 | L6: ÚTILES DE ESCRITORIO Y OFICINA | M6: =SUM(I153,I187,I207,I264,I288) -> 0 | N6: Enero- Diciembre
H7: Julio - Agosto | K7: 3 | L7: PAGO POR TRABAJOS DIRIGIDOS Y PASANTIAS | M7: =SUM(I7,I33,I42,I50,I53,I59,I62,I69,I86,I145,I193,I217,I238,I265,I286) -> 0 | N7: Enero- Diciembre
E8: Seguimiento al POA 2026 | H8: Enero- Diciembre | K8: 4 | L8: CONSULTORES INDIVIDUALES DE LÍNEA | M8: =SUM(I8,I28,I38,I48,I57,I66,I137,I172,I192,I216,I259,I272,I285) -> 0 | N8: Enero- Diciembre
H9: Enero- Diciembre | K9: 5 | L9: EQUIPO DE COMPUTACIÓN | M9: =I11+I52+I56+I78+I83+I209 -> 0 | N9: Enero- Diciembre
H10: Enero- Diciembre | K10: 6 | L10: CAPACITACIÓN DEL PERSONAL | M10: =I13+I29+I41 -> 0 | N10: Enero- Diciembre
H11: Enero- Diciembre | K11: 7 | L11: PASAJES AL INTERIOR DEL PAIS | M11: =I25+I36+I46+I97+I133+I168+I255+I266 -> 0 | N11: Enero- Diciembre
H12: Enero- Diciembre | K12: 8 | L12: VIATICOS POR VIAJES AL INTERIORDEL PAIS | M12: =I26+I37+I47+I84+I98+I134+I169+I188+I212+I234+I257+I267 -> 0 | N12: Enero- Diciembre
H13: Enero- Diciembre | K13: 9 | L13: MANTENIMIENTO Y REPARACION DE INMUEBLES | M13: =I27+I65 -> 0 | N13: Enero- Diciembre
E14: Seguimiento y evaluación al POA 2026 | H14: Abril | K14: 10 | L14: GASTOS POR REFRIGERIOS AL PERSONAL PERMANENTE, EVENTUAL Y CONSULTORES INDIVIDUALES DE LINEA DE LAS INSTITUCIONES PUBLICAS | M14: =I30+I71+I79 -> 0 | N14: Enero- Diciembre
H15: Abril | K15: 11 | L15: OTROS GASTOS POR CONCEPTO DE INSTALACION, MANTENIMIENTO Y REPARACION | M15: =I32+I89 -> 0 | N15: Enero- Diciembre
E16: Elaboracion del Plan Estrategico Empresarial de la EPTAM | H16: Diciembre | K16: 12 | L16: LIBROS,MANUALES Y REVISTAS | M16: =I35+I201+I225 -> 0 | N16: Enero- Diciembre
H17: Diciembre | K17: 13 | L17: COMISIONES Y GASTOS BANCARIOS | M17: =I39+I173 -> 0 | N17: Enero- Diciembre
E18: Elaboracion de un manual de procedimientos. | H18: Diciembre | K18: 14 | L18: SERVICIOS DE IMPRENTA, FOTOCOPIADO Y FOTOGRÁFICOS | M18: =I40+I106+I175 -> 0 | N18: Enero- Diciembre
H19: Diciembre | K19: 15 | L19: GASTOS JUDICIALES | M19: =I49+I58 -> 0 | N19: Enero- Diciembre
K20: 16 | L20: PUBLICIDAD | M20: =I67+I194+I239 -> 0 | N20: Enero- Diciembre
K21: 17 | L21: OTROS SERVICIOS | M21: =I70 -> 0 | N21: Enero- Diciembre
K22: 18 | L22: MATERIAL DE LIMPIEZA E HIGIENE | M22: =I74+I118+I152+I186+I282 -> 0 | N22: Enero- Diciembre
K23: 20 | L23: UTILES Y MATERIALES ELECTRICOS | N23: Enero- Diciembre
K24: 0 | L24: EQUIPOS DE OFICINA Y MUEBLES | M24: 0 | N24: 0
K25: 21 | L25: DERECHOS SOBRE BIENES INTANGIBLES | N25: Enero- Diciembre
K26: 22 | L26: DERECHOS SOBRE BIENES INTANGIBLES | N26: Enero- Diciembre
K27: 23 | L27: COMUNICACIONES | M27: 840 | N27: Enero- Diciembre
K28: 24 | L28: ENERGIA ELECTRICA | M28: 27780 | N28: Enero- Diciembre
K29: 25 | L29: AGUA | M29: 19740 | N29: Enero- Diciembre
K30: 26 | L30: TELEFONIA | M30: 17250 | N30: Enero- Diciembre
K31: 27 | L31: INTERNET | M31: 8811 | N31: Enero- Diciembre
K32: 28 | L32: VIATICOS POR VIAJE AL INTERIOR DEL PAIS | M32: 35616 | N32: Enero- Diciembre
K33: 29 | L33: SEGUROS | M33: 3300 | N33: Enero- Diciembre
K34: 30 | L34: TRANSPORTE DE PERSONAL | M34: 620 | N34: Enero- Diciembre
K35: 31 | L35: MANTENIMIENTO Y REPARACIÓN VEHICULOS MAQUINARIA Y EQUIPO | M35: 1400 | N35: Enero- Diciembre
K36: 32 | L36: AUDITORIAS EXTERNAS | M36: 50400 | N36: Enero- Diciembre
K37: 33 | L37: COMISIONES Y GASTOS BANCARIOS | M37: 2700 | N37: Enero- Diciembre
K38: 34 | L38: LAVANDERIA, LIMPIEZA E HIGIENE | M38: 23750 | N38: Enero- Diciembre
... K43: 39 | L43: PERIODICOS Y BOLETINES | M43: 1500 | N43: Enero- Diciembre
L44: HILADOS, TELAS, FIBRAS Y ALGODON | M44: 1625 | N44: Enero- Diciembre
L45: COMBUSTIBLES, LUBRICANTES Y DERIVADOS PARA CONSUMO | M45: 6648 | N45: Enero- Diciembre
...

Sheet Form 2.1
B2: FORMULARIO N° 2.1
B3: PRESUPUESTO INSTITUCIONAL PLURIANUAL DE RECURSOS
B5: GESTIÓN:
B6: ENTIDAD:
B8: GRUPO | C8: DENOMINACIÓN | G8: FUENTE DE FINANCIAMIENTO | H8: ORGANISMO FINANCIADOR | I8: 2026 | J8: 2027 | K8: 2028 | L8: 2029 | M8: 2030
I9: PROG. | J9: PROG. | K9: PROG. | L9: PROG. | M9: PROG.
B10: 11000 | C10: INGRESOS DE OPERACIÓN
B11: 12000 | C11: VENTA DE BIENES Y SERVICIOS DE LAS ADMINISTRACIONES PÚBLICAS
B12: 13000 | C12: INGRESOS POR IMPUESTOS
B13: 14000 | C13: REGALÍAS
B14: 15000 | C14: TASAS, DERECHOS Y OTROS INGRESOS
B15: 16000 | C15: INTERESES Y OTRAS RENTAS DE LA PROPIEDAD
B16: 17000 | C16: CONTRIBUCIONES A LA SEGURIDAD SOCIAL
B17: 18000 | C17: DONACIONES CORRIENTES
B18: 19000 | C18: TRANSFERENCIAS CORRIENTES
B19: 21000 | C19: RECURSOS PROPIOS DE CAPITAL
B20: 22000 | C20: DONACIONES DE CAPITAL
B21: 23000 | C21: TRANSFERENCIAS DE CAPITAL
... B30: 39000 | C30: INCREMENTO DE OTROS PASIVOS Y APORTES DE CAPITAL
B31: TOTAL
B32: Nota: La columna del 2018 se desprenderán del PGE aprobado.
B35: RESPONSABLES DE LOS COMPROMISOS | D35: NOMBRE Y CARGO | K35: FIRMA
B36: MAE
B37: RESPONSABLE DE PLANIFICACIÓN
B38: RESPONSABLE DE PRESUPUESTO
B39: RESPONSABLE QUE ELABORA
M40: FECHA:

Sheet Form 2.2
C2: FORMULARIO N° 2.2
C4: PRESUPUESTO INSTITUCIONAL PLURIANUAL DE GASTOS
C6: GESTIÓN:
C7: ENTIDAD:
B9: SECTOR | C9: PROGRAMA | F9: GRUPO | G9: CONCEPTO | H9: FUENTE DE FINANCIAMIENTO | I9: ORGANISMO FINANCIADOR | J9: 2026 | K9: 2027 | L9: 2028 | M9: 2029 | N9: 2030
C10: CÓDIGO | D10: DENOMINACIÓN | E10: SISIN | J10: PROG. | K10: PROG. | L10: PROG. | M10: PROG. | N10: PROG.
G11: FUNCIONAMIENTO/OPERACIONES
F12: 10000 | G12: Servicios Personales
F13: 20000 | G13: Servicios No Personales
F14: 30000 | G14: Materiales y Suministros
F15: 40000 | G15: Activos Reales
F16: 50000 | G16: Activos Financieros
F17: 60000 | G17: Servicio de la Deuda Pública y Disminución de Otros Pasivos
F18: 70000 | G18: Transferencias
F19: 80000 | G19: Impuestos, Regalías y Tasas
F20: 90000 | G20: Otros Gastos
F21: INVERSIÓN PÚBLICA
E22: 000004574857 | F22: Proyecto 1
E23: 000004574523 | F23: Proyecto 2
E24: 001522852288 | F24: Proyecto N
C25: TOTAL
C27: RESPONSABLES DE LOS COMPROMISOS | E27: NOMBRE Y CARGO | L27: FIRMA
C28: MAE
C29: RESPONSABLE DE PLANIFICACIÓN
C30: RESPONSABLE DE PRESUPUESTO
C31: RESPONSABLE QUE ELABORA
N32: FECHA:
C33: PROG.: Programado

Sheet Form 3
B2: FORMULARIO N° 3
B4: RESUMEN DE PRESUPUESTO INSTITUCIONAL PLURIANUAL DE GASTOS POR PROGRAMAS ARTICULADO A LA ACCIÓN DE MEDIANO PLAZO
B6: GESTIÓN:
B7: ENTIDAD:
B9: ACCIÓN DE MEDIANO PLAZO (A) | E9: PROGRAMA PRESUPUESTARIO | G9: PROGRAMACIÓN DEL PRESUPUESTO PLURIANUAL DE GASTOS (Bs)
G10: 2026 | H10: 2027 | I10: 2028 | J10: 2029 | K10: 2030
B11: CÓDIGO | C11: DENOMINACIÓN | D11: PRODUCTO O RESULTADO | E11: CÓDIGO | F11: DENOMINACIÓN | G11: PROG. | H11: PROG. | I11: PROG. | J11: PROG. | K11: PROG.
B17: TOTAL
B19: RESPONSABLES DE LOS COMPROMISOS | D19: NOMBRE Y CARGO | I19: FIRMA
B20: MAE
B21: RESPONSABLE DE PLANIFICACIÓN
B22: RESPONSABLE DE PRESUPUESTO
B23: RESPONSABLE QUE ELABORA
K24: FECHA:
B25: PROG.: Programado

Sheet Form 5
B2: FORMULARIO N° 5
B3: OBJETO DEL GASTO 12100 "PERSONAL EVENTUAL"
B5: GESTIÓN:
B6: ENTIDAD:
B8: OBJETIVO DEL PUESTO | C8: ÁREA ORGANIZACIONAL A LA CUAL PERTENECE | D8: EQUIVALENCIA* | H8: TIPO DE GASTO | I8: FUENTE DE FINANCIAMIENTO | J8: ORGANISMO FINANCIADOR | K8: DURACIÓN DEL CONTRATO (Meses) | L8: N° DE CASOS | M8: COSTO MENSUAL (En Bs.) | N8: COSTO TOTAL (En Bs.)
D9: NIVEL SALARIAL | E9: DENOMINACIÓN DEL PUESTO | F9: DENOMINACIÓN DEL CARGO | G9: HABER BÁSICO
B20: TOTAL**
B22: RESPONSABLES DE LOS COMPROMISOS | D22: NOMBRE Y CARGO | J22: FIRMA
B23: MAE
B24: RESPONSABLE DE PRESUPUESTO
B25: RESPONSABLE QUE ELABORA
J26: FECHA:
B27: (*) Al momento del contrato
B28: (**) La suma del total, debera realizarse para las ultimas 3 columnas (N de Casos, Costo Mensual y Costo Total

Sheet Form 6
B2: FORMULARIO N° 6
B3: OBJETO DEL GASTO 25220 "CONSULTORES INDIVIDUALES DE LÍNEA"
B5: GESTIÓN:
B6: ENTIDAD:
B8: CARGO | C8: ÁREA ORGANIZACIONAL QUE VALIDE LA CONSULTORIA | D8: OBJETIVO DE LA CONSULTORIA | E8: ACTIVIDADES Y FUNCIONES DEL CONSULTOR | F8: PERFIL DEL CONSULTOR | G8: RESULTADOS ESPERADOS EN TERM. CUANTITAT. Y/O CUALITAT. | H8: CARGO EQUIVALENTE A LA ESCALA SALARIAL | I8: REMUNERACIÓN EQUIVALENTE A LA ESCALA SALARIAL | J8: FUENTE DE FINANCIAMIENTO | K8: ORGANISMO FINANCIADOR | L8: DURACIÓN DEL CONTRATO (Meses) | M8: N° de CASOS | N8: COSTO MENSUAL (En Bs.) | O8: COSTO TOTAL (En Bs.)
B26: TOTAL*
B28: RESPONSABLES DE LOS COMPROMISOS | D28: NOMBRE Y CARGO | H28: FIRMA
B29: MAE
B30: RESPONSABLE DE PRESUPUESTO
B31: RESPONSABLE QUE ELABORA
H32: FECHA:
B33: (*) La suma del total, debera realizarse para las ultimas 3 columnas (N de Casos, Costo Mensual y Costo Total

Sheet Form 7
B2: FORMULARIO N° 7
B3: OBJETO DEL GASTO 25210 "CONSULTORÍAS POR PRODUCTO"
B5: GESTIÓN:
B6: ENTIDAD:
B8: PRODUCTO | C8: ÁREA ORGANIZACIONAL QUE VALIDE LA CONSULTORÍA | D8: OBJETIVO DE LA CONSULTORÍA | E8: ACTIVIDADES Y FUNCIONES DE LA CONSULTORÍA | F8: RESULTADOS ESPERADOS EN TERM. CUANTITAT. Y/O CUALITATIVO | G8: FUENTE DE FINANCIAMIENTO | H8: ORGANISMO FINANCIADOR | I8: DURACIÓN DEL CONTRATO (Meses) | J8: N° DE CASOS | K8: COSTO MENSUAL (En Bs.) | L8: COSTO TOTAL (En Bs.)
B26: TOTAL*
B28: RESPONSABLES DE LOS COMPROMISOS | D28: NOMBRE Y CARGO | H28: FIRMA
B29: MAE
B30: RESPONSABLE DE PRESUPUESTO
B31: RESPONSABLE QUE ELABORA
H32: FECHA:
B33: (*) La suma del total, debera realizarse para las ultimas 3 columnas (N de Casos, Costo Mensual y Costo Total
B34: Nota: En caso de poseer Auditorias Externas, para el caso del nivel central y entidades descentralizadas, el formulario puede ser adecuado al llenado de este formulario.

Sheet Form 9
B2: FORMULARIO N° 9
B3: PROGRAMACIÓN DE INGRESOS POR UNIDAD DE NEGOCIO
B4: (Expresado en Bolivianos y Cantidades)
B5: GESTIÓN:
B6: ENTIDAD:
B8: UNIDAD DE NEGOCIO Y/O LÍNEA DE PRODUCTO | C8: DETALLE | D8: INGRESOS 2025 | G8: PROGRAMADO PRESUPUESTO 2026 | H8: 2026
D9: INGRESOS (A JULIO) | E9: INGRESOS ESTIMADOS (AGO. - DIC.) | F9: TOTAL INGRESOS | H9: ENERO | I9: FEBRERO | J9: MARZO | K9: ABRIL | L9: MAYO | M9: JUNIO | N9: JULIO | O9: AGOSTO | P9: SEPTIEMBRE | Q9: OCTUBRE | R9: NOVIEMBRE | S9: DICIEMBRE
C10: Ingresos (Bs)
C11: Ventas (Cantidad*)
C12: Precio Promedio (Bs)
C13: Ingresos (Bs)
C14: Ventas (Cantidad*)
C15: Precio Promedio (Bs)
C16: Ingresos (Bs)
C17: Ventas (Cantidad*)
C18: Precio Promedio
C19: Ingresos (Bs)
C20: Ventas (Cantidad*)
C21: Precio Promedio (Bs)
... C39: Precio Promedio (Bs)
B40: (*) Cantidad: Se refiere a la unidad de medida de volúmen como ser: Litros, Kilogramos, Toneladas, KW y otros
B42: RESPONSABLES DE LOS COMPROMISOS | E42: NOMBRE Y CARGO | P42: FIRMA
B43: MAE
B44: RESPONSABLE DE PRESUPUESTO
B45: RESPONSABLE QUE ELABORA
P46: FECHA:

Sheet Form 8
B2: FORMULARIO N° 8
B4: VOLÚMENES DE PRODUCCIÓN POR UNIDAD DE NEGOCIO Y/O LÍNEA DE PRODUCTO
B5: (Expresado en Cantidades y Bolivianos)
B6: GESTIÓN:
B7: ENTIDAD:
B9: UNIDAD DE NEGOCIO Y/O LÍNEA DE PRODUCTO | C9: DETALLE | D9: 2025 | G9: PROGRAMADO PRESUPUESTO 2026 | H9: 2026
D10: PRODUCCIÓN (A JULIO) | E10: ESTIMADO DE PRODUCCIÓN (AGO. - DIC.) | F10: TOTAL PRODUCCIÓN | H10: ENERO | I10: FEBRERO | J10: MARZO | K10: ABRIL | L10: MAYO | M10: JUNIO | N10: JULIO | O10: AGOSTO | P10: SEPTIEMBRE | Q10: OCTUBRE | R10: NOVIEMBRE | S10: DICIEMBRE
C11: Cantidad (*)
C12: Bs
C13: Cantidad (*)
C14: Bs
C15: Cantidad (*)
C16: Bs
C17: Cantidad (*)
C18: Bs
C19: Cantidad (*)
C20: Bs
C21: Cantidad (*)
C22: Bs
... C42: Bs
B43: (*) Cantidad: Se refiere a la unidad de medida de volúmen como ser: Litros, Kilogramos, Toneladas, KW y otros
B45: RESPONSABLES DE LOS COMPROMISOS | D45: NOMBRE Y CARGO | P45: FIRMA
B46: MAE
B47: RESPONSABLE DE PRESUPUESTO
B48: RESPONSABLE QUE ELABORA
P49: FECHA:

Sheet Form 10
B2: FORMULARIO N° 10
B3: OBJETO DEL GASTO: 71220 - BECAS DE ESTUDIOS OTORGADAS A LOS ESTUDIANTES UNIVERSITARIOS
B5: GESTIÓN:
B6: ENTIDAD:
B8: ÁREA ACADÉMICA O FACULTAD | C8: CARRERA | D8: TIPO DE BECA | E8: DENOMINACIÓN DE LA BECA | F8: NORMA DE APROBACIÓN (VIGENTE) | G8: FECHA DE APROBACIÓN | H8: FUENTE DE FINANCIAMIENTO | I8: ORGANISMO FINANCIADOR | J8: DURACIÓN DE LA BECA (Meses) | K8: N° DE BENEFICIARIOS | L8: COSTO MENSUAL (En Bs.) | M8: COSTO TOTAL (En Bs.)
B19: TOTAL*
B21: RESPONSABLES DE LOS COMPROMISOS | E21: NOMBRE Y CARGO | K21: FIRMA
B22: MAE
B23: RESPONSABLE DE PRESUPUESTO
B24: RESPONSABLE QUE ELABORA
K25: FECHA:
B26: (*) La suma del total, debera realizarse para las ultimas 3 columnas (N de Beneficiarios, Costo Mensual y Costo Total

Sheet Form 11
B2: FORMULARIO N° 11
B3: MEMORIA DE CÁLCULO
B5: OBJETO DEL GASTO XXX "NOMBRE DEL OBJETO DE GASTO"
B6: FUENTE XX - "NOMBRE DE LA FUENTE" ORGANISMO XX - "NOMBRE DEL ORGANISMO"
B7: (Expresado en Cantidades y Bolivianos)
B9: GESTIÓN:
B10: ENTIDAD:
B12: N° | C12: DESCRIPCIÓN | D12: CANTIDAD REQUERIDA | E12: UNIDAD | F12: PRECIO UNITARIO | G12: TOTAL | H12: JUSTIFICACIÓN
B13: (1) | C13: (2) | D13: (3) | E13: (4) | F13: (5) | G13: (6) | H13: (7)
B16: TOTAL OBJETO DEL GASTO
D18: NOMBRE Y CARGO | H18: FIRMA
C19: Elaborado por: | D19: (8)
C20: Aprobado por: | D20: (9)
H21: FECHA:
B22: (1) | C22: Orden correlativo del item requerido
B23: (2) | C23: Descripción del item requerido
B24: (3) | C24: Cantidad del ítem requerido en función a la Unidad de Medida
B25: (4) | C25: Unidad de medida del item requerido, el cual puede ser pieza, mes, Kg, Lts, Mts, etc. (no existe la unidad de medida "Global")
B26: (5) | C26: Precio Unitario del item requerido en funcion a la Unidad de Medida
B27: (6) | C27: Total muestra la multiplicación del Precio por la Cantidad
B28: (7) | C28: Justificación detallada de la necesidad del item requerido
B29: (8) | C29: Nombre, Cargo y Firma del Profesional que elabora la Memoria del Cálculo
B30: (9) | C30: Nombre, Cargo y Firma del Jefe Inmediato Superior que aprueba la Memoria del Cálculo

Sheet Form 12
B2: FORMULARIO N° 12
B4: INVENTARIO DE PRODUCTO TERMINADO POR UNIDAD DE NEGOCIO Y/O LÍNEA DE PRODUCTO
B5: (Expresado en Bolivianos)
B6: GESTIÓN:
B7: ENTIDAD:
B9: UNIDAD DE NEGOCIO Y/O LÍNEA DE PRODUCTO | C9: DETALLE | D9: 2026
D10: ENERO | E10: FEBRERO | F10: MARZO | G10: ABRIL | H10: MAYO | I10: JUNIO | J10: JULIO | K10: AGOSTO | L10: SEPTIEMBRE | M10: OCTUBRE | N10: NOVIEMBRE | O10: DICIEMBRE
C11: Inventario Inicial (Bs)
C12: Inventario Final (Bs)
C13: Inventario Inicial (Bs)
C14: Inventario Final (Bs)
C15: Inventario Inicial (Bs)
C16: Inventario Final (Bs)
C17: Inventario Inicial (Bs)
C18: Inventario Final (Bs)
C19: Inventario Inicial (Bs)
C20: Inventario Final (Bs)
C21: Inventario Inicial (Bs)
C22: Inventario Final (Bs)
... C42: Inventario Final (Bs)
B45: RESPONSABLE | D45: NOMBRE Y CARGO | M45: FIRMA
B46: MAE
B47: RESPONSABLE DE PRESUPUESTO
B48: RESPONSABLE QUE ELABORA
M49: FECHA:
B50: Nota: La aplicación de este formuario es obligatorio para aquellas empresas productivas encargadas de la producción y comercialización de bienes de consumo, industrial, doméstico e intermedio, así como de explotación, exploración y transformación de recursos naturales, cuando corresponda.

Sheet Form 13
D2: FORMULARIO N° 13
D4: GASTOS FINANCIADOS CON RECURSOS DE SALDOS DE CAJA Y BANCOS (CORRIENTE - INVERSIÓN)
D6: GESTIÓN:
D7: ENTIDAD:
D9: RECURSOS
D10: LIBRETA (*) | E10: FUENTE Y ORGANISMO FINANCIADOR | F10: SALDO AL 31/12 DE GESTION ANTERIOR | G10: SALDO AL 31/07 DE GESTION EN CURSO (A) | H10: PROYECCIÓN DE INGRESOS AGO - DIC (B) | I10: PROYECCIÓN DE GASTOS AGO - DIC (C) | J10: SALDO EN CAJA Y BANCOS AL 31/12 D = A+B-C | K10: MONTO A INSCRIBIR
D17: TOTAL
D18: (*) No obligatorio para las Entidades Territoriales Autónomas - ETA
D20: GASTOS
C21: SECTOR | D21: PROGRAMA | F21: ACTIVIDAD/PROYECTO | H21: FUENTE DE FINANCIAMIENTO | I21: ORGANISMO FINANCIADOR | J21: GRUPO DE GASTO/CÓDIGO SISIN | K21: MONTO
D22: CÓDIGO | E22: DENOMINACIÓN | F22: CÓDIGO | G22: DENOMINACIÓN
D23: CORRIENTE | J23: (GRUPO DE GASTO)
D33: SUB TOTAL CORRIENTE
D34: INVERSIÓN | J34: (CÓDIGO SISIN)
D38: SUB TOTAL INVERSIÓN
D39: TOTAL
D41: RESPONSABLES DE LOS COMPROMISOS | F41: NOMBRE Y CARGO | K41: FIRMA
D42: MAE
D43: RESPONSABLE DE PLANFICACION
D44: RESPONSABLE DE PRESUPUESTO
D45: RESPONSABLE QUE ELABORA
K46: FECHA:
